Workbook
Name HELIX_daty: #REF!
Name HELIX_datz: #REF!
Name HELIX_CP3: #REF!
Name asdf: #REF!
Name as: #REF!
Name HELIX_datx: #REF!
Name HELIX_daty: #REF!
Name HELIX_az: #REF!
Name __RMX2: #REF!
Name HELIX_CP1: #REF!
Name HELIX_az: #REF!
Name __RMY1: #REF!
Name HELIX_datx: #REF!
Name wet: #REF!
Name __RMZ2: #REF!
Name er: #REF!
Name wet: #REF!
Name HELIX_CP3: #REF!
Name bss: #REF!
Name QWE: #REF!
Name __RMX1: #REF!
Name HELIX_az: #REF!
Name HELIX_ax: #REF!
Name asdf: #REF!
Name __RMZ1: #REF!
Name HELIX_datz: #REF!
Name __RMZ2: #REF!
Name HELIX_CP2: #REF!
Name as: #REF!
Name HH: #REF!
Name asdf: #REF!
Name __RMX1: #REF!
Name HELIX_CP3: #REF!
Name er: #REF!
Name rz: #REF!
Name er: #REF!
Name __RMX2: #REF!
Name yx: #REF!
Name __RMZ1: #REF!
Name HELIX_CP2: #REF!
Name HELIX_ay: #REF!
Name __RMX1: #REF!
Name sfdh: #REF!
Name HELIX_CP2: #REF!
Name bss: #REF!
Name bss: #REF!
Name HELIX_ay: #REF!
Name HELIX_CP1: #REF!
Name __RMZ1: #REF!
Name yx: #REF!
Name HELIX_datx: #REF!
Name yx: #REF!
Name __RMX2: #REF!
Name rz: #REF!
Name HELIX_CP1: #REF!
Name HELIX_daty: #REF!
Name __RMZ2: #REF!
Name __RMY1: #REF!
Name rz: #REF!
Name __RMY1: #REF!

Sheet 0
A2: _ | B2: ="export default l=>{" -> export default l=>{
A3: _ | B3: ="const h=['','','',''];" -> const h=['','','',''];
A4: _ | B4: ="const k=l[1]||Object();" -> const k=l[1]||Object();
A5: 0 | B5: ="const k"&$A$5&"=_=>Math.max(_,0);" -> const k0=_=>Math.max(_,0);
A6: 1 | B6: ="const k"&$A$6&"=_=>Math.abs(_/1);" -> const k1=_=>Math.abs(_/1);
A7: 2 | B7: ="const k"&$A$7&"=_=>Math.round(_/1);" -> const k2=_=>Math.round(_/1);
A8: 3 | B8: ="const k"&$A$8&"=_=>Math.round(_/100);" -> const k3=_=>Math.round(_/100);
A9: 4 | B9: ="const k"&$A$9&"=_=>Math.round(_*10)/10;" -> const k4=_=>Math.round(_*10)/10;
A10: 5 | B10: ="const k"&$A$10&"=_=>Math.round(_*100)/100;" -> const k5=_=>Math.round(_*100)/100;
A11: 6 | B11: ="const k"&$A$11&"=_=>Math.round(_*1000)/1000;" -> const k6=_=>Math.round(_*1000)/1000;
A12: 7 | B12: ="const k"&$A$12&"=_=>`${_}`?.padStart(2,'0');" -> const k7=_=>`${_}`?.padStart(2,'0');
A13: 8 | B13: ="const k"&$A$13&"=_=>`${_}`?.padStart(3,'0');" -> const k8=_=>`${_}`?.padStart(3,'0');
A14: 9 | B14: ="const k"&$A$14&"=_=>_.toString().split(',');" -> const k9=_=>_.toString().split(',');
A15: 10 | B15: ="const k"&$A$15&"=_=>k[_[0]]&&k[_[0]][_[1]];" -> const k10=_=>k[_[0]]&&k[_[0]][_[1]];
A16: 11 | B16: ="const k"&$A$16&"=_=>k[_[0]]&&k[_[0]][_[1]]||'';" -> const k11=_=>k[_[0]]&&k[_[0]][_[1]]||'';
A17: 12 | B17: ="const k"&$A$17&"=_=>k"&$A$16&"([_[0],_[1]])[_[2]]||'';" -> const k12=_=>k11([_[0],_[1]])[_[2]]||'';
A18: 13 | B18: ="const k"&$A$18&"=_=>k"&$A$16&"([_[0],_[2]])[_[1]]||'';" -> const k13=_=>k11([_[0],_[2]])[_[1]]||'';
A19: 14 | B19: ="const k"&$A$19&"=_=>k"&$A$16&"([_[0],_[2]])[_[1]]==null?0:1;" -> const k14=_=>k11([_[0],_[2]])[_[1]]==null?0:1;
A20: 15 | B20: ="const k"&$A$20&"=_=>k"&$A$19&"(_)?k"&$A$16&"([_[0],_[2]])[_[1]]:_[3];" -> const k15=_=>k14(_)?k11([_[0],_[2]])[_[1]]:_[3];
A21: 16 | B21: ="const k"&$A$21&"=_=>_.match(/.{2}/g).map(_=>parseInt(_,16));" -> const k16=_=>_.match(/.{2}/g).map(_=>parseInt(_,16));
A23: 0 | B23: ="const h"&$A$23&"=l=>{let l"&$A$64&"=k"&$A$18&"(l);let l"&$A$65&"=k"&$A$14&"(l"&$A$64&");let l"&$A$66&"=[l"&$A$65&"[0]||'',l"&$A$65&"[1]||''];return l"&$A$66&";};" -> const h0=l=>{let l0=k13(l);let l1=k9(l0);let l2=[l1[0]||'',l1[1]||''];return l2;};
A24: 1 | B24: ="const h"&$A$24&"=l=>{let l"&$A$64&"=k"&$A$14&"(l[0]);let l"&$A$65&"=l"&$A$64&".map(_=>`${_}${l[1]}`);let l"&$A$66&"=l"&$A$65&".join(' ');return l"&$A$66&";};" -> const h1=l=>{let l0=k9(l[0]);let l1=l0.map(_=>`${_}${l[1]}`);let l2=l1.join(' ');return l2;};
A25: 2 | B25: ="const h"&$A$25&"=l=>{let l"&$A$64&"=k"&$A$18&"(l);let l"&$A$65&"=k"&$A$14&"(l"&$A$64&");let l"&$A$66&"=Number(l"&$A$65&"[0]||0)+Number(l"&$A$65&"[1]||0);return l"&$A$66&";};" -> const h2=l=>{let l0=k13(l);let l1=k9(l0);let l2=Number(l1[0]||0)+Number(l1[1]||0);return l2;};
A26: 3 | B26: ="const h"&$A$26&"=l=>{let l"&$A$64&"=k"&$A$18&"(l);let l"&$A$65&"=k"&$A$14&"(l"&$A$64&");let l"&$A$66&"=[Number(l"&$A$65&"[0]||0),Number(l"&$A$65&"[1]||0)];return l"&$A$66&";};" -> const h3=l=>{let l0=k13(l);let l1=k9(l0);let l2=[Number(l1[0]||0),Number(l1[1]||0)];return l2;};
A27: 4 | B27: ="const h"&$A$27&"=l=>{let l"&$A$64&"=Number();for(let i=1;i<l.length;"&"i"&"++){l"&$A$64&"+=!k"&$A$16&"([l[0],l[i]])?0:1;}return l"&$A$64&";};" -> const h4=l=>{let l0=Number();for(let i=1;i<l.length;i++){l0+=!k11([l[0],l[i]])?0:1;}return l0;};
A28: 5 | B28: ="const h"&$A$28&"=l=>{let l"&$A$64&"=Number();let l"&$A$65&"=k"&$A$16&"(l);for(let i=0;i<l[3]+1;i++){l"&$A$64&"+=l"&$A$65&"[l[2]+i]==null?0:1;}return l"&$A$64&";};" -> const h5=l=>{let l0=Number();let l1=k11(l);for(let i=0;i<l[3]+1;i++){l0+=l1[l[2]+i]==null?0:1;}return l0;};
A29: 6 | B29: ="const h"&$A$29&"=l=>{let l"&$A$64&"=Number();let l"&$A$65&"=k"&$A$16&"(l);for(let i=2;i<l.length;i++){l"&$A$64&"+=l"&$A$65&"[l[i]]==null?0:1;}return l"&$A$64&";};" -> const h6=l=>{let l0=Number();let l1=k11(l);for(let i=2;i<l.length;i++){l0+=l1[l[i]]==null?0:1;}return l0;};
A30: 7 | B30: ="const h"&$A$30&"=l=>{let l"&$A$64&"=((l||0)-50)*Math.PI/50;let l"&$A$65&"=Math.cos(l"&$A$64&");let l"&$A$66&"=Math.sin(l"&$A$64&");let l"&$A$67&"=[l"&$A$65&",l"&$A$66&"];return l"&$A$67&";};" -> const h7=l=>{let l0=((l||0)-50)*Math.PI/50;let l1=Math.cos(l0);let l2=Math.sin(l0);let l3=[l1,l2];return l3;};
A31: 8 | B31: ="const h"&$A$31&"=l=>{let l"&$A$64&"=Number();for(let i=2;i<l.length;i++){let l"&$A$65&"=k"&$A$16&"([l[0],l[i]]);l"&$A$64&"+=l"&$A$65&"[l[1]]==null?0:1;}return l"&$A$64&";};" -> const h8=l=>{let l0=Number();for(let i=2;i<l.length;i++){let l1=k11([l[0],l[i]]);l0+=l1[l[1]]==null?0:1;}return l0;};
A32: 9 | B32: ="const hh"&$A$32&"=l=>{let l"&$A$64&"=Number();let l"&$A$65&"=l.slice(1);for(let i=0;i<100;i++){let l"&$A$66&"=h7([l[0],i,...l"&$A$65&"]);l"&$A$64&"+=!l"&$A$66&"?0:1;}return l"&$A$64&";};" -> const hh9=l=>{let l0=Number();let l1=l.slice(1);for(let i=0;i<100;i++){let l2=h7([l[0],i,...l1]);l0+=!l2?0:1;}return l0;};
A33: 10 | B33: ="const h"&$A$33&"=l=>{let l"&$A$64&"=k"&$A$16&"(['2',l[0]]);return l"&$A$64&"[l[1]]==null&&l"&$A$64&"[l[1]+"&COLUMN('2'!$O:$O)-COLUMN('2'!$N:$N)&"]==null?'0 0':`${l"&$A$64&"[l[1]]||0}px ${l"&$A$64&"[l[1]+"&COLUMN('2'!$O:$O)-COLUMN('2'!$N:$N)&"]||0}px`;};" -> const h10=l=>{let l0=k11(['2',l[0]]);return l0[l[1]]==null&&l0[l[1]+1]==null?'0 0':`${l0[l[1]]||0}px ${l0[l[1]+1]||0}px`;};
A34: 11 | B34: ="const h"&$A$34&"=[0||"&ROW('1'!$57:$57)-2&","&ROW('1'!$58:$58)-2&","&ROW('1'!$59:$59)-2&","&ROW('1'!$76:$76)-2&","&ROW('1'!$77:$77)-2&","&ROW('1'!$78:$78)-2&","&ROW('1'!$95:$95)-2&","&ROW('1'!$96:$96)-2&","&ROW('1'!$97:$97)-2&","&ROW('1'!$114:$114)-2&","&ROW('1'!$115:$115)-2&","&ROW('1'!$116:$116)-2&","&ROW('1'!$133:$133)-2&","&ROW('1'!$134:$134)-2&","&ROW('1'!$135:$135)-2&","&ROW('1'!$152:$152)-2&","&ROW('1'!$153:$153)-2&","&ROW('1'!$154:$154)-2&","&ROW('1'!$171:$171)-2&","&ROW('1'!$172:$172)-2&","&ROW('1'!$173:$173)-2&","&ROW('1'!$190:$190)-2&","&ROW('1'!$191:$191)-2&","&ROW('1'!$192:$192)-2&","&ROW('1'!$209:$209)-2&","&ROW('1'!$210:$210)-2&","&ROW('1'!$211:$211)-2&","&ROW('1'!$228:$228)-2&","&ROW('1'!$229:$229)-2&","&ROW('1'!$230:$230)-2&"];" -> const h11=[0||55,56,57,74,75,76,93,94,95,112,113,114,131,132,133,150,151,152,169,170,171,188,189,190,207,208,209,226,227,228];
A35: 12 | B35: ="const h"&$A$35&"=`feColorMatrix type='matrix' values='0.33 0.33 0.33 0 0 0.33 0.33 0.33 0 0 0.33 0.33 0.33 0 0 0 0 0 1 0'></feColorMatrix`;" -> const h12=`feColorMatrix type='matrix' values='0.33 0.33 0.33 0 0 0.33 0.33 0.33 0 0 0.33 0.33 0.33 0 0 0 0 0 1 0'></feColorMatrix`;
A36: 13 | B36: {="const h"&$A$36&"=l=>{let l"&$A$64&"=l[1]>="&ROW('3'!$5:$5)-4&"&&l[1]<="&ROW('3'!$304:$304)-4&"?['White','255,255,255,1','FFFFFF']:['Transparent','255,255,255,0','FFFFFF00'];return l"&$A$64&"[l[0]];};"} -> const h13=l=>{let l0=l[1]>=1&&l[1]<=300?['White','255,255,255,1','FFFFFF']:['Transparent','255,255,255,0','FFFFFF00'];return l0[l[0]];};
A37: 14 | B37: ="const h"&$A$37&"=l=>{let l"&$A$64&"=k"&$A$16&"(['2',l[0]]);return l"&$A$64&"[l[1]]==null&&l"&$A$64&"[l[1]+"&COLUMN('2'!$O:$O)-COLUMN('2'!$N:$N)&"]==null?'':` ${l"&$A$64&"[l[1]]||'0'}px${l"&$A$64&"[l[1]+"&COLUMN('2'!$O:$O)-COLUMN('2'!$N:$N)&"]==null?'':` ${l"&$A$64&"[l[1]+1]}px`}`;};" -> const h14=l=>{let l0=k11(['2',l[0]]);return l0[l[1]]==null&&l0[l[1]+1]==null?'':` ${l0[l[1]]||'0'}px${l0[l[1]+1]==null?'':` ${l0[l[1]+1]}px`}`;};
A38: 15 | B38: ="const h"&$A$38&"=l=>{let l"&$A$64&"=Array();if(k[l[0]]!=null){let l"&$A$65&"=Object.keys(k[l[0]]);let l"&$A$66&"=l"&$A$65&".filter(_=>_>=l[1]&&_<=l[2]);l"&$A$64&"=l"&$A$66&".map(_=>Number(_));}return l"&$A$64&";};" -> const h15=l=>{let l0=Array();if(k[l[0]]!=null){let l1=Object.keys(k[l[0]]);let l2=l1.filter(_=>_>=l[1]&&_<=l[2]);l0=l2.map(_=>Number(_));}return l0;};
A39: 16 | B39: ="const h"&$A$39&"=l=>{let l"&$A$64&"=k"&$A$16&"(['2',l[0]]);let l"&$A$65&"=k"&$A$14&"(l"&$A$64&"[l[1]]||[]);let l"&$A$66&"=k"&$A$14&"(l"&$A$64&"[l[1]+1]||[]);return l"&$A$66&"[l[2]]?` ${l"&$A$66&"[l[2]]}%`:(!l"&$A$65&"[l[2]]?'':` ${l"&$A$65&"[l[2]]}px`);};" -> const h16=l=>{let l0=k11(['2',l[0]]);let l1=k9(l0[l[1]]||[]);let l2=k9(l0[l[1]+1]||[]);return l2[l[2]]?` ${l2[l[2]]}%`:(!l1[l[2]]?'':` ${l1[l[2]]}px`);};
A40: 17 | B40: ="const h"&$A$40&"=l=>{let l"&$A$65&"=k"&$A$16&"(['3',l[0]]);let l"&$A$66&"=l"&$A$65&"[l[1]+"&COLUMN('3'!$I:$I)-COLUMN('3'!$B:$B)&"]?`rgba(${l"&$A$65&"[l[1]+"&COLUMN('3'!$I:$I)-COLUMN('3'!$B:$B)&"]})`:'';let l"&$A$67&"=l"&$A$65&"[l[1]+"&COLUMN('3'!$P:$P)-COLUMN('3'!$B:$B)&"]?`#${l"&$A$65&"[l[1]+"&COLUMN('3'!$P:$P)-COLUMN('3'!$B:$B)&"]}`:'';return l"&$A$67&"||l"&$A$66&"||l"&$A$65&"[l[1]]||'White';};" -> const h17=l=>{let l1=k11(['3',l[0]]);let l2=l1[l[1]+7]?`rgba(${l1[l[1]+7]})`:'';let l3=l1[l[1]+14]?`#${l1[l[1]+14]}`:'';return l3||l2||l1[l[1]]||'White';};
A41: 18 | B41: ="const h"&$A$41&"=l=>{let l"&$A$64&"=Number();for(let i=2;i<l.length;i++){let l"&$A$65&"=k"&$A$16&"([l[0],l[i]]);for(let i0=0;i0<10;i0++){let l"&$A$66&"=i0*100;l"&$A$64&"+=l"&$A$65&"[l"&$A$66&"+l[1]]==null?0:1;}}return l"&$A$64&";};" -> const h18=l=>{let l0=Number();for(let i=2;i<l.length;i++){let l1=k11([l[0],l[i]]);for(let i0=0;i0<10;i0++){let l2=i0*100;l0+=l1[l2+l[1]]==null?0:1;}}return l0;};
A42: 19 | B42: ="const h"&$A$42&"=['body>div',...Array.from({length:100},(_,_0)=>`l${k"&$A$12&"(_0)}`),...Array.from({length:100},(_,_0)=>"&"`k${k"&$A$12&"(_0)}`),...Array.from({length:100},(_,_0)=>`t${k"&$A$12&"(_0)}`),...Array.from({length:1000},(_,_0)=>`t${k"&$A$13&"(_0)}`)];" -> const h19=['body>div',...Array.from({length:100},(_,_0)=>`l${k7(_0)}`),...Array.from({length:100},(_,_0)=>`k${k7(_0)}`),...Array.from({length:100},(_,_0)=>`t${k7(_0)}`),...Array.from({length:1000},(_,_0)=>`t${k8(_0)}`)]; | E42: =""
...

Sheet 1
D1: l00 | E1: l01 | F1: l02 | G1: l03 | H1: l04 | I1: l05 | J1: l06 | K1: l07 | L1: l08 | M1: l09 | N1: l10 | O1: l11 | P1: l12 | Q1: l13 | R1: l14 | S1: l15 | T1: l16 | U1: l17 | V1: l18 | W1: l19 | X1: l20 | Y1: l21 | Z1: l22 | AA1: l23 | AB1: l24 | AC1: l25 | AD1: l26 | AE1: l27 | AF1: l28 | AG1: l29 | AH1: l30 | AI1: l31 | AJ1: l32 | AK1: l33 | AL1: l34 | AM1: l35 | AN1: l36 | AO1: l37 | AP1: l38 | AQ1: l39 | AR1: l40 | AS1: l41 | AT1: l42 | AU1: l43 | AV1: l44 | AW1: l45 | AX1: l46 | AY1: l47 | AZ1: l48 | BA1: l49 | BB1: l50 | BC1: l51 | BD1: l52 | BE1: l53 | BF1: l54 | BG1: l55 | BH1: l56 | BI1: l57 | BJ1: l58 | BK1: l59 | BL1: l60 | BM1: l61 | BN1: l62 | BO1: l63 | BP1: l64 | BQ1: l65 | BR1: l66 | BS1: l67 | BT1: l68 | BU1: l69 | BV1: l70 | BW1: l71 | BX1: l72 | BY1: l73 | BZ1: l74 | CA1: l75 | CB1: l76 | CC1: l77 | CD1: l78 | CE1: l79 | CF1: l80 | CG1: l81 | CH1: l82 | CI1: l83 | CJ1: l84 | CK1: l85 | CL1: l86 | CM1: l87 | CN1: l88 | CO1: l89 | CP1: l90 | CQ1: l91 | CR1: l92 | CS1: l93 | CT1: l94 | CU1: l95 | CV1: l96 | CW1: l97 | CX1: l98 | CY1: l99
A2: width self | B2: number
A3: width flex | B3: % all
A4: width max | B4: px all
A5: height flex | B5: % all
A6: height max | B6: px all
A7: height min | B7: % all | C7: 100
A8: aligned min | B8: select 4 | C8: auto
A9: aligned max | B9: select 3 | C9: none
A10: order diagonal | B10: 0 - 99 | C10: 0
A11: order horizontal | B11: % all
A12: order vertical | B12: % all
A13: offset axis x | B13: px,px all
A14: offset axis y | B14: px,px all
A15: margin axis x | B15: px,px all
A16: margin axis y | B16: px,px all
A17: padding axis x | B17: px,px all
A18: padding axis y | B18: px,px all
A19: relation frame | B19: l00 - t99
D20: k00 | E20: k01 | F20: k02 | G20: k03 | H20: k04 | I20: k05 | J20: k06 | K20: k07 | L20: k08 | M20: k09 | N20: k10 | O20: k11 | P20: k12 | Q20: k13 | R20: k14 | S20: k15 | T20: k16 | U20: k17 | V20: k18 | W20: k19 | X20: k20 | Y20: k21 | Z20: k22 | AA20: k23 | AB20: k24 | AC20: k25 | AD20: k26 | AE20: k27 | AF20: k28 | AG20: k29 | AH20: k30 | AI20: k31 | AJ20: k32 | AK20: k33 | AL20: k34 | AM20: k35 | AN20: k36 | AO20: k37 | AP20: k38 | AQ20: k39 | AR20: k40 | AS20: k41 | AT20: k42 | AU20: k43 | AV20: k44 | AW20: k45 | AX20: k46 | AY20: k47 | AZ20: k48 | BA20: k49 | BB20: k50 | BC20: k51 | BD20: k52 | BE20: k53 | BF20: k54 | BG20: k55 | BH20: k56 | BI20: k57 | BJ20: k58 | BK20: k59 | BL20: k60 | BM20: k61 | BN20: k62 | BO20: k63 | BP20: k64 | BQ20: k65 | BR20: k66 | BS20: k67 | BT20: k68 | BU20: k69 | BV20: k70 | BW20: k71 | BX20: k72 | BY20: k73 | BZ20: k74 | CA20: k75 | CB20: k76 | CC20: k77 | CD20: k78 | CE20: k79 | CF20: k80 | CG20: k81 | CH20: k82 | CI20: k83 | CJ20: k84 | CK20: k85 | CL20: k86 | CM20: k87 | CN20: k88 | CO20: k89 | CP20: k90 | CQ20: k91 | CR20: k92 | CS20: k93 | CT20: k94 | CU20: k95 | CV20: k96 | CW20: k97 | CX20: k98 | CY20: k99
A21: width flex | B21: % all
A22: width max | B22: px all
A23: height flex | B23: % all
A24: height max | B24: px all
A25: height min | B25: % all | C25: 100
A26: aligned min | B26: select 3 | C26: none
A27: aligned max | B27: select 3 | C27: none
A28: order diagonal | B28: 0 - 99
A29: order horizontal | B29: % all
A30: order vertical | B30: % all
A31: offset axis x | B31: px,px all
A32: offset axis y | B32: px,px all
A33: margin axis x | B33: px,px all
A34: margin axis y | B34: px,px all
A35: padding axis x | B35: px,px all
A36: padding axis y | B36: px,px all
A37: relation frame | B37: l00 - t99
D38: t00 | E38: t01 | F38: t02 | G38: t03 | H38: t04 | I38: t05 | J38: t06 | K38: t07 | L38: t08 | M38: t09 | N38: t10 | O38: t11 | P38: t12 | Q38: t13 | R38: t14 | S38: t15 | T38: t16 | U38: t17 | V38: t18 | W38: t19 | X38: t20 | Y38: t21 | Z38: t22 | AA38: t23 | AB38: t24 | AC38: t25 | AD38: t26 | AE38: t27 | AF38: t28 | AG38: t29 | AH38: t30 | AI38: t31 | AJ38: t32 | AK38: t33 | AL38: t34 | AM38: t35 | AN38: t36 | AO38: t37 | AP38: t38 | AQ38: t39 | AR38: t40 | AS38: t41 | AT38: t42 | AU38: t43 | AV38: t44 | AW38: t45 | AX38: t46 | AY38: t47 | AZ38: t48 | BA38: t49 | BB38: t50 | BC38: t51 | BD38: t52 | BE38: t53 | BF38: t54 | BG38: t55 | BH38: t56 | BI38: t57 | BJ38: t58 | BK38: t59 | BL38: t60 | BM38: t61 | BN38: t62 | BO38: t63 | BP38: t64 | BQ38: t65 | BR38: t66 | BS38: t67 | BT38: t68 | BU38: t69 | BV38: t70 | BW38: t71 | BX38: t72 | BY38: t73 | BZ38: t74 | CA38: t75 | CB38: t76 | CC38: t77 | CD38: t78 | CE38: t79 | CF38: t80 | CG38: t81 | CH38: t82 | CI38: t83 | CJ38: t84 | CK38: t85 | CL38: t86 | CM38: t87 | CN38: t88 | CO38: t89 | CP38: t90 | CQ38: t91 | CR38: t92 | CS38: t93 | CT38: t94 | CU38: t95 | CV38: t96 | CW38: t97 | CX38: t98 | CY38: t99
A39: width flex | B39: % all
A40: width max | B40: px all
...

Sheet 2
B1: left | C1: right | D1: top | E1: bottom | F1: ground | G1: blur I | H1: blur II | I1: axis x | J1: axis y | K1: axis z | L1: blur I | M1: blur II | N1: axis x | O1: axis y | P1: axis z | Q1: left | R1: right | S1: top | T1: bottom | U1: outline | V1: offset | W1: paint | X1: paint | Y1: angle nw | Z1: angle nw | AA1: angle ne | AB1: angle ne | AC1: angle sw | AD1: angle sw | AE1: angle se | AF1: angle se | AG1: slide x | AH1: slide y | AI1: scale x | AJ1: scale y | AK1: rotate z | AL1: origin z | AM1: horizontal | AN1: vertical | AO1: direct | AP1: invert | AQ1: index
B2: px all | C2: px all | D2: px all | E2: px all | F2: select 3 | G2: px | H2: px all | I2: px all | J2: px all | K2: boolean | L2: px | M2: px all | N2: px all | O2: px all | P2: boolean | Q2: px | R2: px | S2: px | T2: px | U2: px | V2: px all | W2: select 4 | X2: select 4 | Y2: px,px | Z2: %,% | AA2: px,px | AB2: %,% | AC2: px,px | AD2: %,% | AE2: px,px | AF2: %,% | AG2: % all | AH2: % all | AI2: number | AJ2: number | AK2: deg all | AL2: select 8 | AM2: select 5 | AN2: select 6 | AO2: boolean | AP2: boolean | AQ2: number
B3: auto | C3: auto | D3: auto | E3: auto | F3: auto | G3: auto | H3: auto | K3: false | L3: auto | M3: auto | P3: false | Q3: auto | R3: auto | S3: auto | T3: auto | U3: auto | V3: auto | W3: solid | X3: solid | AI3: 1 | AJ3: 1 | AK3: 0 | AL3: center | AM3: center | AN3: start | AO3: false | AP3: false | AQ3: auto
A4: all | B4: 0 | C4: 1 | D4: 2 | E4: 3
A5: l00 | B5: 2 | C5: 2 | D5: 2 | E5: 2 | U5: 1 | V5: -3
A6: l01 | B6: 2 | C6: 2 | D6: 2 | E6: 2 | U6: 1 | V6: -3
A7: l02 | B7: 2 | C7: 2 | D7: 2 | E7: 2 | U7: 1 | V7: -3
A8: l03 | B8: 2 | C8: 2 | D8: 2 | E8: 2 | U8: 1 | V8: -3
A9: l04 | B9: 2 | C9: 2 | D9: 2 | E9: 2 | U9: 1 | V9: -3
A10: l05 | B10: 2 | C10: 2 | D10: 2 | E10: 2 | U10: 1 | V10: -3
A11: l06 | B11: 2 | C11: 2 | D11: 2 | E11: 2 | U11: 1 | V11: -3
A12: l07 | B12: 2 | C12: 2 | D12: 2 | E12: 2 | U12: 1 | V12: -3
A13: l08 | B13: 2 | C13: 2 | D13: 2 | E13: 2 | U13: 1 | V13: -3
A14: l09 | B14: 2 | C14: 2 | D14: 2 | E14: 2 | U14: 1 | V14: -3
A15: l10 | B15: 2 | C15: 2 | D15: 2 | E15: 2 | U15: 1 | V15: -3
A16: l11 | B16: 2 | C16: 2 | D16: 2 | E16: 2 | U16: 1 | V16: -3
... A304: t99 | B304: 2 | C304: 2 | D304: 2 | E304: 2 | U304: 1 | V304: -3
A305: t000 | G305: 0 | H305: 1 | Q305: 2 | R305: 2 | S305: 2 | T305: 2
A306: t001 | G306: 0 | H306: 1 | Q306: 2 | R306: 2 | S306: 2 | T306: 2
A307: t002 | G307: 0 | H307: 1 | Q307: 2 | R307: 2 | S307: 2 | T307: 2
A308: t003 | G308: 0 | H308: 1 | Q308: 2 | R308: 2 | S308: 2 | T308: 2
A309: t004 | G309: 0 | H309: 1 | Q309: 2 | R309: 2 | S309: 2 | T309: 2
A310: t005 | G310: 0 | H310: 1 | Q310: 2 | R310: 2 | S310: 2 | T310: 2
A311: t006 | G311: 0 | H311: 1 | Q311: 2 | R311: 2 | S311: 2 | T311: 2
A312: t007 | G312: 0 | H312: 1 | Q312: 2 | R312: 2 | S312: 2 | T312: 2
A313: t008 | G313: 0 | H313: 1 | Q313: 2 | R313: 2 | S313: 2 | T313: 2
A314: t009 | G314: 0 | H314: 1 | Q314: 2 | R314: 2 | S314: 2 | T314: 2
A315: t010 | G315: 0 | H315: 1 | Q315: 2 | R315: 2 | S315: 2 | T315: 2
A316: t011 | G316: 0 | H316: 1 | Q316: 2 | R316: 2 | S316: 2 | T316: 2
... A1304: t999 | G1304: 0 | H1304: 1 | Q1304: 2 | R1304: 2 | S1304: 2 | T1304: 2

Sheet 3
B1: shape fill | C1: shade front | D1: shade scope | E1: border fill | F1: outline fill | G1: gradient | H1: gradient | I1: shape fill | J1: shade front | K1: shade scope | L1: border fill | M1: outline fill | N1: gradient | O1: gradient | P1: fills | Q1: front | R1: scope | S1: border | T1: outline | U1: gradient | V1: gradient | W1: display | X1: visible | Y1: blend I | Z1: blend II | AA1: drop fx | AB1: shade | AC1: axis x | AD1: axis y | AE1: bright | AF1: opacity | AG1: opacity | AH1: grayscale | AI1: saturate | AJ1: contrast | AK1: rotation | AL1: gradient | AM1: gradient | AN1: image | AO1: shift I | AP1: shift II
B2: select 130 | C2: select 130 | D2: select 130 | E2: select 130 | F2: select 130 | G2: select 130 | H2: select 130 | I2: r,g,b,a | J2: r,g,b,a | K2: r,g,b,a | L2: r,g,b,a | M2: r,g,b,a | N2: r,g,b,a | O2: r,g,b,a | P2: #hex | Q2: #hex | R2: #hex | S2: #hex | T2: #hex | U2: #hex | V2: #hex | W2: select 3 | X2: select 3 | Y2: select 15 | Z2: boolean | AA2: boolean | AB2: px | AC2: px all | AD2: px all | AE2: % | AF2: % | AG2: % | AH2: % | AI2: % | AJ2: % | AK2: deg all | AL2: select 8 | AM2: select 3 | AN2: select 2 | AO2: px,px | AP2: %,%
B3: auto | C3: auto | D3: auto | E3: auto | F3: auto | G3: auto | H3: auto | W3: auto | X3: auto | Y3: auto | Z3: false | AA3: false | AK3: 0 | AL3: center | AM3: linear | AN3: none
A4: all
A5: l00 | F5: Gray | G5: White | H5: White
A6: l01 | F6: Gray | G6: White | H6: White
A7: l02 | F7: Gray | G7: White | H7: White
A8: l03 | F8: Gray | G8: White | H8: White
A9: l04 | F9: Gray | G9: White | H9: White
A10: l05 | F10: Gray | G10: White | H10: White
A11: l06 | F11: Gray | G11: White | H11: White
A12: l07 | F12: Gray | G12: White | H12: White
A13: l08 | F13: Gray | G13: White | H13: White
A14: l09 | F14: Gray | G14: White | H14: White
A15: l10 | F15: Gray | G15: White | H15: White
A16: l11 | F16: Gray | G16: White | H16: White
... A304: t99 | F304: Gray | G304: White | H304: White
A305: t000 | B305: White | C305: Gray
A306: t001 | B306: White | C306: Gray
A307: t002 | B307: White | C307: Gray
A308: t003 | B308: White | C308: Gray
A309: t004 | B309: White | C309: Gray
A310: t005 | B310: White | C310: Gray
A311: t006 | B311: White | C311: Gray
A312: t007 | B312: White | C312: Gray
A313: t008 | B313: White | C313: Gray
A314: t009 | B314: White | C314: Gray
A315: t010 | B315: White | C315: Gray
A316: t011 | B316: White | C316: Gray
... A1304: t999 | B1304: White | C1304: Gray

Sheet 4
B1: left | C1: right | D1: top | E1: bottom | F1: ground | G1: location | H1: position | I1: position | J1: position | K1: sizes I | L1: sizes II | M1: file local
B2: px | C2: px | D2: px | E2: px | F2: boolean | G2: select 3 | H2: select 8 | I2: px,px | J2: %,% | K2: px,px | L2: %,% | M2: path png
B3: 10 | C3: 10 | D3: 10 | E3: 10 | F3: false | G3: cover | H3: center
A4: l00
A5: l01
A6: l02
A7: l03
A8: l04
A9: l05
A10: l06
A11: l07
A12: l08
A13: l09
A14: l10
A15: l11
... A1303: t999

Sheet 5
B1: left | C1: right | D1: top | E1: bottom | F1: color I | G1: color II | H1: align I | I1: align II | J1: style | K1: size I | L1: size II | M1: file local | N1: input text
B2: px | C2: px | D2: px | E2: px | F2: #hex | G2: #hex | H2: select 4 | I2: select 4 | J2: select 3 | K2: 1 - 9 | L2: px,px | M2: path otf | N2: html text
B3: 10 | C3: 10 | D3: 10 | E3: 10 | H3: auto | I3: auto | J3: none | K3: 4 | L3: 16
A4: l00
A5: l01
A6: l02
A7: l03
A8: l04
A9: l05
A10: l06
A11: l07
A12: l08
A13: l09
A14: l10
A15: l11
... A1303: t999
